Workbook

Sheet 00_README
A1: TIFS Critical Review — Detailed Audit Workbook
A2: Prefilled from the current “From Sound to Shelf” manuscript and supplementary package. Blue-font cells are intended for author input; formula cells are black.
A4: Purpose and use
A5: Workbook purpose | B5: Audit scientific logic, evidence support, review-method integrity, writing quality, visuals, references and TIFS submission readiness.
A6: Central paper idea | B6: A transferable acoustic process must be defined by the exposure received by the fruit—not by repeated source settings.
A7: Source files | B7: From_Sound_to_Shelf_TIFS_Critical_Review_Rewritten.docx; From_Sound_to_Shelf_TIFS_Supplementary_Material.docx; How-to-write-a-great-research-paper PDF; scientific-writing guidance documents.
A8: Evidence boundary | B8: No missing sample sizes, screening counts, effect sizes or experimental results were invented. Unverified fields are marked for completion.
A9: Recommended workflow | B9: 1) Start on Dashboard; 2) resolve Critical actions; 3) verify Claim–Evidence ledger; 4) finish search / reference audit; 5) close figure and table actions; 6) rerun writing audit; 7) complete TIFS compliance.
A11: Scoring scale
A12: Score | B12: Meaning | C12: Operational definition
A13: 0 | B13: Missing / unsupported | C13: Required element absent or claim unsupported.
A14: 1 | B14: Weak | C14: Present but materially inadequate or contradicted.
A15: 2 | B15: Partial | C15: Useful foundation; important verification or revision remains.
A16: 3 | B16: Strong | C16: Scientifically defensible; minor refinement remains.
A17: 4 | B17: Submission-ready | C17: Complete, verified, reproducible and internally consistent.
A19: Colour and cell conventions
A20: Blue font / pale yellow fill | B20: Author input or field that must be completed from records.
A21: Green font | B21: Imported or source-derived content.
A22: Black font | B22: Formula, derived result or completed audit judgement.
A23: Orange fill | B23: Caution / revision needed.
A24: Light red fill | B24: Critical error, unsupported claim or blocking issue.
A25: Purple fill | B25: Control logic, criteria or decision rule.
A26: Teal fill | B26: Key scientific KPI, framework element or visualization anchor.
A29: Sheet map
A30: 01_Dashboard | B30: Submission-readiness KPIs and blocking issues.
A31: 02_Story_Audit | B31: One-line problem, one ping, title, novelty, contribution and scope audit.
A32: 03_Section_Audit | B32: Section-by-section function, strengths, gaps and actions.
A33: 04_Claim_Evidence | B33: Claim-to-evidence ledger with overclaim and qualifier controls.
A34: 05_Study_Comparison | B34: Detailed seven-study comparison matrix.
A35: 06_Evidence_Chain | B35: A–D causal-link heatmap and domain summaries.
A36: 07_Contradictions | B36: Contradictions, hidden variables and decisive tests.
A37: 08_Gaps_Innovations | B37: High-value gaps, experiments, impact and prioritization.
A38: 09_Figure_Audit | B38: Graphical abstract, main and supplementary figure audit.
A39: 10_Table_Audit | B39: Main and supplementary table audit.
A40: 11_Supplement_Audit | B40: Supplementary package completeness and non-duplication audit.
A41: 12_Reference_Audit | B41: All references with verification and claim-support fields.
... A46: 17_Decision_Log | B46: Scope and positioning decisions for co-author alignment.

Sheet 01_Dashboard
A1: TIFS Critical Review Audit Dashboard
A2: Overall readiness reflects scientific integrity, evidence verification, visual package, writing quality and submission compliance.
A4: Overall readiness | E4: Critical open actions | I4: Claims needing verification | P4: Action status
A5: =AVERAGE(C13:C19) | E5: =COUNTIFS('16_Action_Plan'!J4:J17,"Critical",'16_Action_Plan'!L4:L17,"<>Complete") | I5: =COUNTIF('04_Claim_Evidence'!N4:N28,"Needs verification") | P5: Not started | Q5: =COUNTIF('16_Action_Plan'!$L$4:$L$17,P5)
P6: In progress | Q6: =COUNTIF('16_Action_Plan'!$L$4:$L$17,P6)
A7: References not verified | E7: Evidence Grade-D cells | I7: TIFS compliance blockers | P7: Needs verification | Q7: =COUNTIF('16_Action_Plan'!$L$4:$L$17,P7)
A8: =COUNTIF('12_Reference_Audit'!Q4:Q130,"Needs verification") | E8: =COUNTIF('06_Evidence_Chain'!C8:I14,"D") | I8: =COUNTIFS('13_TIFS_Compliance'!H4:H25,"Critical",'13_TIFS_Compliance'!G4:G25,"<>Complete") | P8: Needs revision | Q8: =COUNTIF('16_Action_Plan'!$L$4:$L$17,P8)
P9: Complete | Q9: =COUNTIF('16_Action_Plan'!$L$4:$L$17,P9)
A11: Readiness by audit domain
A12: Domain | B12: Score / 4 | C12: Readiness % | D12: Open critical/high items | E12: Linked sheet | F12: Primary blocker | G12: Owner | H12: Status
A13: Story / positioning | B13: =ROUND(AVERAGE('02_Story_Audit'!E4:E20),2) | C13: ='02_Story_Audit'!B22/100 | D13: =COUNTIFS('02_Story_Audit'!I4:I20,"Critical",'02_Story_Audit'!H4:H20,"<>Complete")+COUNTIFS('02_Story_Audit'!I4:I20,"High",'02_Story_Audit'!H4:H20,"<>Complete") | E13: 02_Story_Audit | F13: Search reproducibility and novelty comparison | H13: In progress
A14: Section completeness | B14: =ROUND(AVERAGE('03_Section_Audit'!G4:G16),2) | C14: =B14/4 | D14: =COUNTIFS('03_Section_Audit'!I4:I16,"Critical",'03_Section_Audit'!H4:H16,"<>Complete")+COUNTIFS('03_Section_Audit'!I4:I16,"High",'03_Section_Audit'!H4:H16,"<>Complete") | E14: 03_Section_Audit | F14: Method, references and declarations | H14: In progress
A15: Claim support | B15: =ROUND(AVERAGE('04_Claim_Evidence'!P4:P28),2) | C15: =B15/4 | D15: =COUNTIFS('04_Claim_Evidence'!O4:O28,"Critical",'04_Claim_Evidence'!N4:N28,"<>Complete")+COUNTIFS('04_Claim_Evidence'!O4:O28,"High",'04_Claim_Evidence'!N4:N28,"<>Complete") | E15: 04_Claim_Evidence | F15: Corpus-bounded findings and overclaim control | H15: In progress
A16: Figures | B16: =ROUND(AVERAGE('09_Figure_Audit'!J4:L10),2) | C16: =B16/4 | D16: =COUNTIFS('09_Figure_Audit'!P4:P10,"Critical",'09_Figure_Audit'!O4:O10,"<>Complete")+COUNTIFS('09_Figure_Audit'!P4:P10,"High",'09_Figure_Audit'!O4:O10,"<>Complete") | E16: 09_Figure_Audit | F16: Figure 3 depends on verified evidence coding | H16: In progress
A17: Tables / supplement | B17: =ROUND(AVERAGE('10_Table_Audit'!R4:R11),2) | C17: =B17/4 | D17: =COUNTIFS('10_Table_Audit'!K4:K11,"Critical",'10_Table_Audit'!J4:J11,"<>Complete")+COUNTIFS('11_Supplement_Audit'!J4:J10,"Critical",'11_Supplement_Audit'!I4:I10,"<>Complete") | E17: 10_Table_Audit | F17: S1–S3 and S5 incomplete | H17: In progress
A18: References | B18: =IFERROR((COUNTIF('12_Reference_Audit'!Q4:Q130,"Complete")/COUNTA('12_Reference_Audit'!A4:A130))*4,0) | C18: =B18/4 | D18: =COUNTIFS('12_Reference_Audit'!P4:P130,"High",'12_Reference_Audit'!Q4:Q130,"<>Complete") | E18: 12_Reference_Audit | F18: Source-level verification pending | H18: Not started
A19: TIFS compliance | B19: =IFERROR((COUNTIF('13_TIFS_Compliance'!F4:F25,"Yes")/COUNTA('13_TIFS_Compliance'!A4:A25))*4,0) | C19: =B19/4 | D19: =COUNTIFS('13_TIFS_Compliance'!H4:H25,"Critical",'13_TIFS_Compliance'!G4:G25,"<>Complete") | E19: 13_TIFS_Compliance | F19: Current journal instructions and declarations | H19: Not started
A22: Top blocking actions
A23: Action ID | B23: Action | C23: Why it matters | D23: Priority | E23: Status | F23: Owner | G23: Due date | H23: Linked item
A24: ='16_Action_Plan'!A4 | B24: ='16_Action_Plan'!C4 | C24: ='16_Action_Plan'!D4 | D24: ='16_Action_Plan'!J4 | E24: ='16_Action_Plan'!L4 | F24: ='16_Action_Plan'!K4 | G24: ='16_Action_Plan'!M4 | H24: ='16_Action_Plan'!O4
A25: ='16_Action_Plan'!A5 | B25: ='16_Action_Plan'!C5 | C25: ='16_Action_Plan'!D5 | D25: ='16_Action_Plan'!J5 | E25: ='16_Action_Plan'!L5 | F25: ='16_Action_Plan'!K5 | G25: ='16_Action_Plan'!M5 | H25: ='16_Action_Plan'!O5
A26: ='16_Action_Plan'!A6 | B26: ='16_Action_Plan'!C6 | C26: ='16_Action_Plan'!D6 | D26: ='16_Action_Plan'!J6 | E26: ='16_Action_Plan'!L6 | F26: ='16_Action_Plan'!K6 | G26: ='16_Action_Plan'!M6 | H26: ='16_Action_Plan'!O6
A27: ='16_Action_Plan'!A7 | B27: ='16_Action_Plan'!C7 | C27: ='16_Action_Plan'!D7 | D27: ='16_Action_Plan'!J7 | E27: ='16_Action_Plan'!L7 | F27: ='16_Action_Plan'!K7 | G27: ='16_Action_Plan'!M7 | H27: ='16_Action_Plan'!O7
A28: ='16_Action_Plan'!A8 | B28: ='16_Action_Plan'!C8 | C28: ='16_Action_Plan'!D8 | D28: ='16_Action_Plan'!J8 | E28: ='16_Action_Plan'!L8 | F28: ='16_Action_Plan'!K8 | G28: ='16_Action_Plan'!M8 | H28: ='16_Action_Plan'!O8
A29: ='16_Action_Plan'!A9 | B29: ='16_Action_Plan'!C9 | C29: ='16_Action_Plan'!D9 | D29: ='16_Action_Plan'!J9 | E29: ='16_Action_Plan'!L9 | F29: ='16_Action_Plan'!K9 | G29: ='16_Action_Plan'!M9 | H29: ='16_Action_Plan'!O9
A30: ='16_Action_Plan'!A10 | B30: ='16_Action_Plan'!C10 | C30: ='16_Action_Plan'!D10 | D30: ='16_Action_Plan'!J10 | E30: ='16_Action_Plan'!L10 | F30: ='16_Action_Plan'!K10 | G30: ='16_Action_Plan'!M10 | H30: ='16_Action_Plan'!O10
A31: ='16_Action_Plan'!A11 | B31: ='16_Action_Plan'!C11 | C31: ='16_Action_Plan'!D11 | D31: ='16_Action_Plan'!J11 | E31: ='16_Action_Plan'!L11 | F31: ='16_Action_Plan'!K11 | G31: ='16_Action_Plan'!M11 | H31: ='16_Action_Plan'!O11
A32: ='16_Action_Plan'!A12 | B32: ='16_Action_Plan'!C12 | C32: ='16_Action_Plan'!D12 | D32: ='16_Action_Plan'!J12 | E32: ='16_Action_Plan'!L12 | F32: ='16_Action_Plan'!K12 | G32: ='16_Action_Plan'!M12 | H32: ='16_Action_Plan'!O12
A33: ='16_Action_Plan'!A13 | B33: ='16_Action_Plan'!C13 | C33: ='16_Action_Plan'!D13 | D33: ='16_Action_Plan'!J13 | E33: ='16_Action_Plan'!L13 | F33: ='16_Action_Plan'!K13 | G33: ='16_Action_Plan'!M13 | H33: ='16_Action_Plan'!O13

Sheet 02_Story_Audit
A1: Story, Positioning and “One Ping” Audit
A2: Score each item 0–4. The current judgements are prefilled from the manuscript; revise them after author verification.
A3: ID | B3: Audit item | C3: Submission standard | D3: Current manuscript evidence / formulation | E3: Score (0–4) | F3: Weight | G3: Weighted score | H3: Status | I3: Priority | J3: Required action | K3: Owner | L3: Due date | M3: Source / location | N3: Reviewer notes
A4: S01 | B4: One-line real problem | C4: Identifies a field-level, consequential problem—not merely a missing review. | D4: Acoustic treatments are specified by frequency, dB, power and time although these do not define receiver exposure. | E4: 4 | F4: 5 | G4: =E4*F4 | H4: High | I4: Keep wording identical in title logic, abstract, introduction, cover letter and conclusion. | L4: Introduction ¶1–5
A5: S02 | B5: One reusable “ping” | C5: Reader can repeat one sharp insight after closing the paper. | D5: The treatment is what the fruit receives, not what the machine emits. | E5: 4 | F5: 5 | G5: =E5*F5 | H5: Critical | I5: Prevent secondary ideas from competing with receiver exposure. | L5: Introduction / conclusion
A6: S03 | B6: Title–scope alignment | C6: Title states hook, contribution and bounded receiver. | D6: “From Sound to Shelf … Intact Fruit” aligns with mechanisms, evidence and process design. | E6: 4 | F6: 4 | G6: =E6*F6 | H6: Medium | I6: Retain “intact fruit”; avoid implying all food acoustic technologies are comprehensively reviewed. | L6: Title page
A7: S04 | B7: Concrete opening example | C7: Page one uses a memorable physical counterexample before abstraction. | D7: The 25 kHz example contrasts contact strain, cavitation, boundary-layer forcing and support motion. | E7: 4 | F7: 4 | G7: =E7*F7 | H7: High | I7: Keep Figure 1 visually consistent with this example. | L7: Introduction ¶1 / Figure 1
A8: S05 | B8: Quantified evidence gap | C8: Gap includes corpus-bounded quantitative result. | D8: 0/7 fruit motion; 0/7 support isolation; 0/7 external confirmation. | E8: 3 | F8: 5 | G8: =E8*F8 | H8: Critical | I8: Complete reproducible search and independent coding before finalizing the 0/7 claim. | L8: Table 2 / Figure 3 / Supplement
A9: S06 | B9: Novelty versus prior reviews | C9: States exactly how this review differs from ultrasound/application reviews. | D9: Mechanism- and receiver-centred taxonomy plus causal-closure audit and transfer test. | E9: 3 | F9: 5 | G9: =E9*F9 | H9: High | I9: Add a concise “difference from prior reviews” paragraph or comparison box. | L9: End of Introduction
A10: S07 | B10: Three refutable contributions | C10: Contributions are specific, evidence-linked and capable of failure. | D10: Reclassification; evidence-chain diagnosis; receiver-centred process design. | E10: 4 | F10: 5 | G10: =E10*F10 | H10: High | I10: Maintain only these three headline contributions. | L10: Introduction bullets
A11: S08 | B11: Central testable hypothesis | C11: Predictor and failure condition are explicit. | D11: Receiver motion / validated strain should outperform nominal source settings for a mechanical effect. | E11: 4 | F11: 5 | G11: =E11*F11 | H11: Critical | I11: Keep conditional wording; do not present as established fact. | L11: Introduction / Section 8
A12: S09 | B12: Failure conditions | C12: Paper states evidence that would weaken or reject the framework. | D12: Matched exposure without improved prediction implies an incomplete mechanism. | E12: 4 | F12: 4 | G12: =E12*F12 | H12: High | I12: Repeat failure condition in Figure 4 and conclusion. | L12: Table 3 / Section 8
A13: S10 | B13: Critical review position | C13: Paper compares, explains disagreement and separates fact from interpretation. | D13: Contradiction matrix links disagreement to hidden variables and decisive tests. | E13: 4 | F13: 4 | G13: =E13*F13 | H13: High | I13: Preserve neutral wording; avoid implying earlier results are false. | L13: Section 5 / Table 3
A14: S11 | B14: Scope boundary | C14: Primary receiver and comparator literatures are explicitly separated. | D14: Intact fruit is focal; sensing, liquid ultrasound, transport and mechanobiology are comparators. | E14: 4 | F14: 4 | G14: =E14*F14 | H14: High | I14: State this boundary in abstract and methods. | L14: Abstract / Section 2
A15: S12 | B15: Shelf relevance | C15: Outcome extends beyond single firmness values to longitudinal shelf performance. | D15: Section 7 defines trajectories, safety, damage and usable shelf period. | E15: 3 | F15: 4 | G15: =E15*F15 | H15: High | I15: Check that each shelf-performance claim has direct literature support and does not imply validated extension. | L15: Section 7
... A20: S17 | B20: TIFS fit | C20: Connects critical synthesis to food-industry application, scale-up and decisions. | D20: Mechanisms → evidence → process design → shelf performance. | E20: 4 | F20: 4 | G20: =E20*F20 | H20: High | I20: Keep plant physiology subordinate to food-process metrology. | L20: Whole manuscript
A22: Weighted readiness (%) | B22: =ROUND(SUM(G4:G20)/(4*SUM(F4:F20))*100,1)

Sheet 03_Section_Audit
A1: Section-by-Section Manuscript Audit
A2: Each section should perform one scientific job and move the narrative from mechanism to evidence to process design to shelf relevance.
A3: Section | B3: Primary job | C3: Current strength | D3: Principal weakness / risk | E3: Evidence or completion needed | F3: Current word count | G3: Score (0–4) | H3: Status | I3: Priority | J3: Required action | K3: Owner | L3: Due date | M3: Source / page | N3: Notes
A4: Highlights | B4: State five concise findings without overclaiming. | C4: Clear receiver-centred story and 0/7 signal. | D4: “None of seven” requires completed review protocol. | E4: Final search and coding record; final word/character limits. | F4: 51 | G4: 3 | H4: Needs verification | I4: High | J4: Verify journal format and evidence boundary. | M4: Manuscript
A5: Abstract | B5: Problem → gap → critical synthesis → framework → impact. | C5: Strong source-versus-receiver problem and quantified gap. | D5: Methods and 0/7 claim depend on unfinished search documentation. | E5: Final database record; exact abstract word limit check. | F5: 244 | G5: 3 | H5: Needs verification | I5: Critical | J5: Update only after search audit is locked. | M5: Manuscript
A6: 1. Introduction: the missing link from sound to shelf | B6: Concrete example, gap, position and three contributions. | C6: Excellent 25 kHz counterexample and refutable contributions. | D6: Novelty versus existing reviews could be more explicit. | E6: One compact prior-review comparison paragraph. | F6: 456 | G6: 4 | H6: Complete | I6: High | J6: Add explicit novelty comparison if space permits. | M6: Manuscript
A7: 2. Review scope and critical evidence method | B7: Define search, eligibility, grading and claim boundary. | C7: Honest question-led review boundary and grade definitions. | D7: Databases, counts, exclusions and reviewer agreement unfinished. | E7: Complete S1–S3 from actual records. | F7: 268 | G7: 2 | H7: Needs verification | I7: Critical | J7: Treat as the main submission blocker. | M7: Manuscript
A8: 3. Mechanisms: one acoustic spectrum, different physical technologies | B8: Reclassify technologies by transfer path and receiver variable. | C8: Strong physics-based taxonomy and 25 kHz example. | D8: Deployment judgements may appear subjective. | E8: Define maturity criteria or soften labels. | F8: 0 | G8: 3 | H8: Needs revision | I8: High | J8: Move detailed maturity rubric to supplement. | M8: Manuscript
A9: 4. Evidence: what is established and what remains latent | B9: Compare study clusters and audit causal closure. | C9: Distinguishes outcome evidence from exposure evidence. | D9: Seven studies are a narrow corpus and connected lineage. | E9: Search completeness; full-text verification; second reviewer. | F9: 0 | G9: 3 | H9: Needs verification | I9: Critical | J9: Lock extraction and evidence coding. | M9: Manuscript
A10: 5. Contradictions reveal hidden exposure variables | B10: Explain disagreement through hidden variables and decisive tests. | C10: High-value synthesis; not a paper-by-paper catalogue. | D10: Some comparator claims may require source-level verification. | E10: Claim–reference audit for every contradiction. | F10: 125 | G10: 3 | H10: Needs verification | I10: High | J10: Use Table 3 as the organizing spine. | M10: Manuscript
A11: 6. Receiver-centred process design | B11: Operationalize the solution. | C11: Exposure Passport, Operating Window and receiver equivalence are coherent. | D11: Proposed tools are not yet validated standards. | E11: Use “proposed”; distinguish minimum reporting from validation. | F11: 0 | G11: 4 | H11: Complete | I11: High | J11: Keep receiver equivalence explicitly testable. | M11: Manuscript
A12: 7. From treatment to shelf performance | B12: Connect exposure to longitudinal product value. | C12: Moves beyond single firmness endpoints. | D12: Risk of promising shelf-life extension without validation. | E12: Use “shelf-relevant trajectory”; support each outcome domain. | F12: 0 | G12: 3 | H12: Needs revision | I12: High | J12: Audit wording around shelf extension. | M12: Manuscript
A13: 8. Decisive experiments and staged validation | B13: Specify experiments that can support or reject the framework. | C13: Motion clamp and route separation produce informative outcomes. | D13: No pilot variance, sample size or equivalence margin yet. | E13: Pilot design and statistical analysis plan. | F13: 0 | G13: 3 | H13: Needs verification | I13: High | J13: Complete S5 before claiming implementability. | M13: Manuscript
A14: 9. Limitations and boundary conditions | B14: State where the framework may fail or require different variables. | C14: Transparent and scientifically protective. | D14: Could distinguish review limitations from framework limitations. | E14: Split into two short subgroups. | F14: 194 | G14: 4 | H14: Complete | I14: Medium | J14: Retain explicit failure conditions. | M14: Manuscript
A15: 10. Conclusions | B15: Answer the question and broaden to field significance. | C15: Returns to receiver exposure and transferable process. | D15: Avoid repeating all tools and digital-control outlook. | E15: Tight 3–4 paragraph conclusion. | F15: 224 | G15: 4 | H15: Complete | I15: Medium | J15: End with one decisive sentence. | M15: Manuscript
... A17: References | B17: Provide accurate, relevant and traceable support. | C17: Broad evidence base with 127 references. | D17: Full source-level claim audit and current-reference verification incomplete. | E17: Complete Reference Audit sheet. | F17: 0 | G17: 2 | H17: Needs verification | I17: Critical | J17: Verify every load-bearing claim and DOI. | M17: Manuscript

Sheet 04_Claim_Evidence
A1: Claim–Evidence Ledger
A2: Every load-bearing claim should have a source, an evidence type, a boundary, a qualifier where needed, and a verification decision.
A3: Claim ID | B3: Claim / sentence | C3: Claim class | D3: Importance | E3: Evidence type | F3: Supporting manuscript evidence | G3: Key references | H3: Support status | I3: Overclaim risk | J3: Corpus / scope boundary | K3: Required qualifier or revised wording | L3: Verification task | M3: Owner | N3: Status | O3: Priority | P3: Readiness score | Q3: Notes
A4: C01 | B4: The same frequency band can encode physically different food processes. | C4: Established physical principle | D4: Core | E4: Direct measurement | F4: Figure 1 / Table 1 taxonomy | G4: 1–13, 38, 48, 62–71 | H4: Supported | I4: Low | J4: Across technologies; not a universal dose comparison | K4: Retain; state that bands are typical and overlapping. | L4: Verify representative references for each modality. | N4: Needs verification | O4: High | P4: 3
A5: C02 | B5: Nominal frequency, dB, generator power and time do not uniquely define receiver exposure. | C5: Established + inference | D5: Core | E5: Direct measurement | F5: Equations / source-to-shelf chain | G5: 10–13, 62–70 | H5: Supported | I5: Low | J5: Route-specific; receiver variable differs by modality | K5: Retain. | L5: Check all equations and units. | N5: Needs verification | O5: High | P5: 3
A6: C03 | B6: Fruit is an evolving mechanical receiver whose transfer function changes with state. | C6: Supported inference | D6: Core | E6: Supported association | F6: Section 3.3; Figure 2 | G6: 14–25, 75–84 | H6: Supported | I6: Medium | J6: Mechanical characterization; not proof that actuation improves quality | K6: Use “changes with state” and avoid universal resonance claims. | L6: Verify commodity-specific evidence. | N6: Needs verification | O6: High | P6: 3
A7: C04 | B7: Modal features can track firmness or maturity in selected commodities. | C7: Established in bounded systems | D7: Supporting | E7: Direct measurement | F7: Sensing comparator section | G7: 14–25, 75–84 | H7: Supported | I7: Low | J7: Commodity- and geometry-specific | K7: Add “selected commodities and configurations.” | L7: Verify external validation and negative results. | N7: Needs verification | O7: Medium | P7: 3
A8: C05 | B8: Driving a measured fruit mode has not been shown to improve shelf quality. | C8: Absence / boundary claim | D8: Core | E8: Evidence-based inference | F8: Sensing-versus-actuation distinction | G8: 14–25, 75–84 | H8: Partial | I8: Medium | J8: Retained corpus and cited comparator literature | K8: Use “the reviewed evidence does not establish…” | L8: Search specifically for mode-targeted intervention studies. | N8: Needs verification | O8: Critical | P8: 2
A9: C06 | B9: Among seven retained airborne-fruit studies, none measured fruit motion. | C9: Corpus-bounded quantitative finding | D9: Core | E9: Direct extraction | F9: Table 2 / Figure 3 / S3 | G9: 26–30, 32–33 | H9: Partial | I9: High | J9: Only the retained corpus under the final protocol | K9: Use “none of the seven studies retained here…” | L9: Complete search, full-text verification and second-reviewer check. | N9: Needs verification | O9: Critical | P9: 2
A10: C07 | B10: Among seven retained studies, none isolated support-mediated transfer. | C10: Corpus-bounded quantitative finding | D10: Core | E10: Direct extraction | F10: Table 2 / Figure 3 / S3 | G10: 26–30, 32–33 | H10: Partial | I10: High | J10: Only the retained corpus | K10: Same corpus-bounded qualifier. | L10: Complete coding and source-page log. | N10: Needs verification | O10: Critical | P10: 2
A11: C08 | B11: Among seven retained studies, none externally validated exposure–quality transfer. | C11: Corpus-bounded quantitative finding | D11: Core | E11: Direct extraction | F11: Table 2 / Figure 3 / S3 | G11: 26–30, 32–33 | H11: Partial | I11: High | J11: Only the retained corpus | K11: Same corpus-bounded qualifier. | L11: Verify no external replication / transfer in full texts. | N11: Needs verification | O11: Critical | P11: 2
A12: C09 | B12: The detached-tomato papers form a connected evidence lineage rather than independent replication. | C12: Evidence-based inference | D12: Core | E12: Authorship / protocol comparison | F12: Section 4.1 | G12: 26–30 | H12: Supported | I12: Medium | J12: Connected investigators, material and treatment logic | K12: Use neutral wording; do not diminish observed outcomes. | L12: Check author and protocol overlap. | N12: Needs verification | O12: High | P12: 3
A13: C10 | B13: Different nominal dB values within the lineage do not reconstruct equivalent fruit exposure. | C13: Established physical principle applied to studies | D13: Supporting | E13: Direct extraction + inference | F13: Section 4.1 | G13: 28, 30 | H13: Supported | I13: Low | J13: 80 versus 100 dB are source-side labels | K13: Retain. | L13: Verify reported source levels and measurement locations. | N13: Needs verification | O13: High | P13: 3
A14: C11 | B14: Firmness alone cannot establish cell-wall preservation. | C14: Critical interpretation | D14: Supporting | E14: Comparative evidence | F14: Section 4.4 / contradiction matrix | G14: 58–61, 92–94 | H14: Supported | I14: Low | J14: Firmness integrates multiple structures and states | K14: Retain. | L14: Check that cited studies support contrasting mechanisms. | N14: Needs verification | O14: High | P14: 3
A15: C12 | B15: Mechanosensitive calcium/redox pathways are biologically plausible but unproven as the route in intact fruit. | C15: Hypothesis boundary | D15: Core | E15: Supported association | F15: Section 4.5 | G15: 85–90 | H15: Supported | I15: Low | J15: Cell / plant plausibility does not establish intact-fruit strain | K15: Retain conditional wording. | L15: Verify exact mechanistic scope of each source. | N15: Needs verification | O15: High | P15: 3
... A28: C25 | B28: The next breakthrough is closing the loaded-field → support → fruit-motion → tissue-exposure → shelf-response chain. | C28: Synthesis / position | D28: Core | E28: Evidence-based inference | F28: Conclusion | G28: Whole review | H28: Supported | I28: Low | J28: Scientific position, not empirical result | K28: Retain as final message. | L28: Ensure each link has a corresponding audit field. | N28: Complete | O28: High | P28: 4

Sheet 05_Study_Comparison
A1: Primary Airborne-Fruit Study Comparison
A2: Detailed comparison of research question, receiver, methods, measurements, findings, limitations and contribution. “Verify full text” fields must be completed from source papers.
A3: Study ID | B3: Full citation / DOI | C3: Receiver / context | D3: Research question | E3: Assumed mechanism / theory | F3: Reported source recipe | G3: Sample / experimental unit | H3: Treatment geometry / chamber | I3: Physical exposure measurements | J3: Environmental controls | K3: Biological / quality measurements | L3: Main reported finding | M3: Statistical / replication notes | N3: Agreement with lineage | O3: Disagreement / novelty | P3: Principal limitation | Q3: Contribution | R3: Independent replication? | S3: Full-text verified? | T3: Audit notes
A4: Kim et al. 2015 [26] Detached tomato | B4: Kim JY, Lee JS, Kwon TR, Lee SI, Kim JA, Lee GM, et al. (2015). Sound waves delay tomato fruit ripening by negatively regulating ethylene biosynthesis and signaling genes. Postharvest Biology and Technology, 110, 43-50. https://doi.org/10.1016/j.postharvbio.2015.07.015 | https://doi.org/10.1016/j.postharvbio.2015.07.015 | C4: Kim et al. 2015 [26] Detached tomato | D4: Can airborne sound delay ripening, implicitly through a sound-responsive physiological pathway? | E4: Mechanical / physiological pathway inferred from treatment label; verify exact author theory. | F4: 1 kHz; six-hour treatment; reported source level in original paper | G4: Verify full text: sample size, chamber/run unit and biological replicate structure. | H4: Verify full text: source distance, orientation, load, chamber dimensions and support. | I4: No fruit motion; no support isolation; nominal field only | J4: Verify temperature, humidity, airflow, gas history, shams and background vibration. | K4: Colour, firmness, ethylene / CO₂ trajectories and ripening-related gene expression | L4: Repeated phenotype and molecular association within one treatment system | M4: Verify randomization, nesting, repeated measures and correct experimental unit. | N4: Builds on / is adjacent to the connected tomato or plant evidence lineage. | O4: See manuscript Table 2 and Section 5 for divergence. | P4: Receiver motion, tray vibration, microclimate and chamber-level replication remain unresolved | Q4: Established the core detached-tomato observation and motivated later molecular work | R4: No external confirmation identified in retained corpus. | S4: No
A5: Kim et al. 2016 [27] Detached tomato | B5: Kim JY, Ahn HR, Kim ST, Min CW, Lee SI, Kim JA, et al. (2016). Sound wave affects the expression of ethylene biosynthesis-related genes through control of transcription factors RIN and HB-1. Plant Biotechnology Reports, 10(6), 437-445. https://doi.org/10.1007/s11816-016-0419-2 | https://doi.org/10.1007/s11816-016-0419-2 | C5: Kim et al. 2016 [27] Detached tomato | D5: Does sound alter ethylene-biosynthesis-related transcription through RIN and HB-1? | E5: Mechanical / physiological pathway inferred from treatment label; verify exact author theory. | F5: Related 1 kHz treatment lineage | G5: Verify full text: sample size, chamber/run unit and biological replicate structure. | H5: Verify full text: source distance, orientation, load, chamber dimensions and support. | I5: No fruit motion or route separation reported | J5: Verify temperature, humidity, airflow, gas history, shams and background vibration. | K5: Transcription factors and ethylene-biosynthesis-related genes | L5: Molecular association consistent with the earlier phenotype | M5: Verify randomization, nesting, repeated measures and correct experimental unit. | N5: Builds on / is adjacent to the connected tomato or plant evidence lineage. | O5: See manuscript Table 2 and Section 5 for divergence. | P5: Same lineage; physical exposure and alternative routes remain latent | Q5: Extended the proposed pathway to transcriptional control | R5: No external confirmation identified in retained corpus. | S5: No
A6: Kim et al. 2018 [28] Detached tomato | B6: Kim JY, Kim SK, Jung J, Jeong MJ, Ryu CM. (2018). Exploring the sound-modulated delay in tomato ripening through expression analysis of coding and non-coding RNAs. Annals of Botany. https://doi.org/10.1093/aob/mcy134 | https://doi.org/10.1093/aob/mcy134 | C6: Kim et al. 2018 [28] Detached tomato | D6: Which coding and non-coding RNAs accompany delayed ripening? | E6: Mechanical / physiological pathway inferred from treatment label; verify exact author theory. | F6: 1 kHz; nominal 80 dB reported | G6: Verify full text: sample size, chamber/run unit and biological replicate structure. | H6: Verify full text: source distance, orientation, load, chamber dimensions and support. | I6: No receiver motion or support isolation reported | J6: Verify temperature, humidity, airflow, gas history, shams and background vibration. | K6: Time-course expression of coding and non-coding RNAs | L6: Temporal molecular association under the treatment label | M6: Verify randomization, nesting, repeated measures and correct experimental unit. | N6: Builds on / is adjacent to the connected tomato or plant evidence lineage. | O6: See manuscript Table 2 and Section 5 for divergence. | P6: Nominal source level does not reconstruct fruit exposure; maturity alignment can confound interpretation | Q6: Broadened the molecular signature and temporal evidence | R6: No external confirmation identified in retained corpus. | S6: No
A7: Kim et al. 2023 [29] Detached tomato | B7: Kim JY, Lee HJ, Jeong MJ. (2023). Epigenetic regulation for delaying tomato fruit ripening through histone modification by specific sound wave treatment. Postharvest Biology and Technology, 197, 112211. https://doi.org/10.1016/j.postharvbio.2022.112211 | https://doi.org/10.1016/j.postharvbio.2022.112211 | C7: Kim et al. 2023 [29] Detached tomato | D7: Does sound exposure alter histone modification linked with ripening delay? | E7: Mechanical / physiological pathway inferred from treatment label; verify exact author theory. | F7: Related 1 kHz treatment lineage | G7: Verify full text: sample size, chamber/run unit and biological replicate structure. | H7: Verify full text: source distance, orientation, load, chamber dimensions and support. | I7: No discriminating mechanical control reported | J7: Verify temperature, humidity, airflow, gas history, shams and background vibration. | K7: Histone modification and ripening-related outcomes | L7: Epigenetic association within a bounded system | M7: Verify randomization, nesting, repeated measures and correct experimental unit. | N7: Builds on / is adjacent to the connected tomato or plant evidence lineage. | O7: See manuscript Table 2 and Section 5 for divergence. | P7: Receiver route and causal temporal sequence remain unclosed | Q7: Added an epigenetic layer to the connected evidence lineage | R7: No external confirmation identified in retained corpus. | S7: No
A8: Jeong et al. 2023 [30] Detached tomato | B8: Jeong MJ, Ko BJ, Kim JY. (2023). Mass spectrometry-based metabolomics study for delay tomato fruit ripening by sound waves. Journal of Analytical Science and Technology, 14(1), 27. https://doi.org/10.1186/s40543-023-00384-3 | https://doi.org/10.1186/s40543-023-00384-3 | C8: Jeong et al. 2023 [30] Detached tomato | D8: Which metabolites accompany delayed ripening under sound treatment? | E8: Mechanical / physiological pathway inferred from treatment label; verify exact author theory. | F8: 1 kHz; nominal 100 dB reported | G8: Verify full text: sample size, chamber/run unit and biological replicate structure. | H8: Verify full text: source distance, orientation, load, chamber dimensions and support. | I8: No fruit motion; limited environmental control described in review corpus | J8: Verify temperature, humidity, airflow, gas history, shams and background vibration. | K8: Selected metabolomic differences and ripening phenotype | L8: Association between treatment label and metabolite set | M8: Verify randomization, nesting, repeated measures and correct experimental unit. | N8: Builds on / is adjacent to the connected tomato or plant evidence lineage. | O8: See manuscript Table 2 and Section 5 for divergence. | P8: Different nominal level from related papers; selected sampling time may reflect maturity divergence | Q8: Added metabolomic evidence but not mechanical closure | R8: No external confirmation identified in retained corpus. | S8: No
A9: Ozkurt & Altuntas 2018 [32] Fruit on living strawberry plants | B9: Ozkurt H, Altuntas O. (2018). Quality Parameter Levels of Strawberry Fruit in Response to Different Sound Waves at 1000 Hz with Different dB Values (95, 100, 105 dB). Agronomy, 8(7), 127. https://doi.org/10.3390/agronomy8070127 | https://doi.org/10.3390/agronomy8070127 | C9: Ozkurt & Altuntas 2018 [32] Fruit on living strawberry plants | D9: Do different source levels at 1000 Hz affect fruit quality on plants? | E9: Mechanical / physiological pathway inferred from treatment label; verify exact author theory. | F9: 1000 Hz at 95, 100 and 105 dB | G9: Verify full text: sample size, chamber/run unit and biological replicate structure. | H9: Verify full text: source distance, orientation, load, chamber dimensions and support. | I9: No direct fruit motion or support-transfer measurement | J9: Verify temperature, humidity, airflow, gas history, shams and background vibration. | K9: Fruit quality parameters after repeated whole-plant exposure | L9: Bounded plant-level association with randomized block design | M9: Verify randomization, nesting, repeated measures and correct experimental unit. | N9: Builds on / is adjacent to the connected tomato or plant evidence lineage. | O9: See manuscript Table 2 and Section 5 for divergence. | P9: Receiver is the entire living plant, not a detached stored fruit; chronic exposure and chamber effects differ | Q9: Provides adjacent biological evidence, not validation of detached-fruit processing | R9: No external confirmation identified in retained corpus. | S9: No
A10: Altuntas & Ozkurt 2019 [33] Fruit on living tomato plants | B10: Altuntas O, Ozkurt H. (2019). The assessment of tomato fruit quality parameters under different sound waves. Journal of Food Science and Technology, 56(4), 2186-2194. https://doi.org/10.1007/s13197-019-03701-0 | https://doi.org/10.1007/s13197-019-03701-0 | C10: Altuntas & Ozkurt 2019 [33] Fruit on living tomato plants | D10: Do several sound frequencies alter tomato fruit quality during development? | E10: Mechanical / physiological pathway inferred from treatment label; verify exact author theory. | F10: 600, 1240 and 1600 Hz applied in successive weeks | G10: Verify full text: sample size, chamber/run unit and biological replicate structure. | H10: Verify full text: source distance, orientation, load, chamber dimensions and support. | I10: No direct fruit motion or route isolation | J10: Verify temperature, humidity, airflow, gas history, shams and background vibration. | K10: Fruit quality parameters under whole-plant exposure | L10: Exploratory association across development | M10: Verify randomization, nesting, repeated measures and correct experimental unit. | N10: Builds on / is adjacent to the connected tomato or plant evidence lineage. | O10: See manuscript Table 2 and Section 5 for divergence. | P10: Frequency is confounded with treatment order and developmental time | Q10: Shows why time, order and receiver identity must be separated | R10: No external confirmation identified in retained corpus. | S10: No

Sheet 06_Evidence_Chain
A1: Causal Evidence-Chain Audit
A2: A–D grades describe whether each specific causal link was established; they do not grade whether a reported outcome was statistically significant.
A4: Retained studies | D4: Receiver motion measured | G4: Support isolated | J4: External confirmation | M4: Total Grade-D cells
A5: 7 | D5: =COUNTIF(D8:D14,"A")+COUNTIF(D8:D14,"B") | G5: =COUNTIF(E8:E14,"A")+COUNTIF(E8:E14,"B") | J5: =COUNTIF(I8:I14,"A")+COUNTIF(I8:I14,"B") | M5: =COUNTIF(C8:I14,"D")
A7: Study | B7: Receiver system | C7: Loaded field | D7: Receiver motion | E7: Support isolated | F7: Thermal / gas sham | G7: Fruit-level unit | H7: Internal replication | I7: External confirmation | J7: Average grade | K7: Grade-D count | L7: Mechanistic closure | M7: Overall interpretation | N7: Source page / note | O7: Reviewer note
A8: Kim 2015 | B8: Detached tomato | C8: C | D8: D | E8: D | F8: C | G8: B | H8: B | I8: D | J8: =ROUND(AVERAGE(VLOOKUP(C8,Lists!$M$2:$N$5,2,FALSE),VLOOKUP(D8,Lists!$M$2:$N$5,2,FALSE),VLOOKUP(E8,Lists!$M$2:$N$5,2,FALSE),VLOOKUP(F8,Lists!$M$2:$N$5,2,FALSE),VLOOKUP(G8,Lists!$M$2:$N$5,2,FALSE),VLOOKUP(H8,Lists!$M$2:$N$5,2,FALSE),VLOOKUP(I8,Lists!$M$2:$N$5,2,FALSE)),2) | K8: =COUNTIF(C8:I8,"D") | L8: =IF(AND(D8<>"D",E8<>"D",I8<>"D"),"Partly closed","Open") | M8: Repeated outcome signal with latent mechanical exposure. | N8: Supplementary Table S3; verify exact source pages.
A9: Kim 2016 | B9: Detached tomato | C9: C | D9: D | E9: D | F9: C | G9: C | H9: B | I9: D | J9: =ROUND(AVERAGE(VLOOKUP(C9,Lists!$M$2:$N$5,2,FALSE),VLOOKUP(D9,Lists!$M$2:$N$5,2,FALSE),VLOOKUP(E9,Lists!$M$2:$N$5,2,FALSE),VLOOKUP(F9,Lists!$M$2:$N$5,2,FALSE),VLOOKUP(G9,Lists!$M$2:$N$5,2,FALSE),VLOOKUP(H9,Lists!$M$2:$N$5,2,FALSE),VLOOKUP(I9,Lists!$M$2:$N$5,2,FALSE)),2) | K9: =COUNTIF(C9:I9,"D") | L9: =IF(AND(D9<>"D",E9<>"D",I9<>"D"),"Partly closed","Open") | M9: Molecular association within the same treatment lineage. | N9: Supplementary Table S3; verify exact source pages.
A10: Kim 2018 | B10: Detached tomato | C10: C | D10: D | E10: D | F10: C | G10: B | H10: B | I10: D | J10: =ROUND(AVERAGE(VLOOKUP(C10,Lists!$M$2:$N$5,2,FALSE),VLOOKUP(D10,Lists!$M$2:$N$5,2,FALSE),VLOOKUP(E10,Lists!$M$2:$N$5,2,FALSE),VLOOKUP(F10,Lists!$M$2:$N$5,2,FALSE),VLOOKUP(G10,Lists!$M$2:$N$5,2,FALSE),VLOOKUP(H10,Lists!$M$2:$N$5,2,FALSE),VLOOKUP(I10,Lists!$M$2:$N$5,2,FALSE)),2) | K10: =COUNTIF(C10:I10,"D") | L10: =IF(AND(D10<>"D",E10<>"D",I10<>"D"),"Partly closed","Open") | M10: Transcriptomic time course without receiver closure. | N10: Supplementary Table S3; verify exact source pages.
A11: Kim 2023 | B11: Detached tomato | C11: C | D11: D | E11: D | F11: C | G11: C | H11: B | I11: D | J11: =ROUND(AVERAGE(VLOOKUP(C11,Lists!$M$2:$N$5,2,FALSE),VLOOKUP(D11,Lists!$M$2:$N$5,2,FALSE),VLOOKUP(E11,Lists!$M$2:$N$5,2,FALSE),VLOOKUP(F11,Lists!$M$2:$N$5,2,FALSE),VLOOKUP(G11,Lists!$M$2:$N$5,2,FALSE),VLOOKUP(H11,Lists!$M$2:$N$5,2,FALSE),VLOOKUP(I11,Lists!$M$2:$N$5,2,FALSE)),2) | K11: =COUNTIF(C11:I11,"D") | L11: =IF(AND(D11<>"D",E11<>"D",I11<>"D"),"Partly closed","Open") | M11: Epigenetic association without a discriminating mechanical control. | N11: Supplementary Table S3; verify exact source pages.
A12: Jeong 2023 | B12: Detached tomato | C12: C | D12: D | E12: D | F12: B | G12: C | H12: C | I12: D | J12: =ROUND(AVERAGE(VLOOKUP(C12,Lists!$M$2:$N$5,2,FALSE),VLOOKUP(D12,Lists!$M$2:$N$5,2,FALSE),VLOOKUP(E12,Lists!$M$2:$N$5,2,FALSE),VLOOKUP(F12,Lists!$M$2:$N$5,2,FALSE),VLOOKUP(G12,Lists!$M$2:$N$5,2,FALSE),VLOOKUP(H12,Lists!$M$2:$N$5,2,FALSE),VLOOKUP(I12,Lists!$M$2:$N$5,2,FALSE)),2) | K12: =COUNTIF(C12:I12,"D") | L12: =IF(AND(D12<>"D",E12<>"D",I12<>"D"),"Partly closed","Open") | M12: Selected metabolomic set and different nominal level. | N12: Supplementary Table S3; verify exact source pages.
A13: Ozkurt & Altuntas 2018 | B13: Fruit on living strawberry plants | C13: C | D13: D | E13: D | F13: C | G13: C | H13: B | I13: D | J13: =ROUND(AVERAGE(VLOOKUP(C13,Lists!$M$2:$N$5,2,FALSE),VLOOKUP(D13,Lists!$M$2:$N$5,2,FALSE),VLOOKUP(E13,Lists!$M$2:$N$5,2,FALSE),VLOOKUP(F13,Lists!$M$2:$N$5,2,FALSE),VLOOKUP(G13,Lists!$M$2:$N$5,2,FALSE),VLOOKUP(H13,Lists!$M$2:$N$5,2,FALSE),VLOOKUP(I13,Lists!$M$2:$N$5,2,FALSE)),2) | K13: =COUNTIF(C13:I13,"D") | L13: =IF(AND(D13<>"D",E13<>"D",I13<>"D"),"Partly closed","Open") | M13: Whole-plant exposure is adjacent evidence, not a detached-fruit process. | N13: Supplementary Table S3; verify exact source pages.
A14: Altuntas & Ozkurt 2019 | B14: Fruit on living tomato plants | C14: C | D14: D | E14: D | F14: C | G14: C | H14: C | I14: D | J14: =ROUND(AVERAGE(VLOOKUP(C14,Lists!$M$2:$N$5,2,FALSE),VLOOKUP(D14,Lists!$M$2:$N$5,2,FALSE),VLOOKUP(E14,Lists!$M$2:$N$5,2,FALSE),VLOOKUP(F14,Lists!$M$2:$N$5,2,FALSE),VLOOKUP(G14,Lists!$M$2:$N$5,2,FALSE),VLOOKUP(H14,Lists!$M$2:$N$5,2,FALSE),VLOOKUP(I14,Lists!$M$2:$N$5,2,FALSE)),2) | K14: =COUNTIF(C14:I14,"D") | L14: =IF(AND(D14<>"D",E14<>"D",I14<>"D"),"Partly closed","Open") | M14: Frequency is confounded with time and order. | N14: Supplementary Table S3; verify exact source pages.
A17: Domain summary
A18: Domain | B18: A count | C18: B count | D18: C count | E18: D count | F18: Mean grade | G18: Interpretive note
A19: Loaded field | B19: =COUNTIF(C$8:C$14,"A") | C19: =COUNTIF(C$8:C$14,"B") | D19: =COUNTIF(C$8:C$14,"C") | E19: =COUNTIF(C$8:C$14,"D") | F19: =ROUND(AVERAGE(VLOOKUP(C$8,Lists!$M$2:$N$5,2,FALSE),VLOOKUP(C$9,Lists!$M$2:$N$5,2,FALSE),VLOOKUP(C$10,Lists!$M$2:$N$5,2,FALSE),VLOOKUP(C$11,Lists!$M$2:$N$5,2,FALSE),VLOOKUP(C$12,Lists!$M$2:$N$5,2,FALSE),VLOOKUP(C$13,Lists!$M$2:$N$5,2,FALSE),VLOOKUP(C$14,Lists!$M$2:$N$5,2,FALSE)),2) | G19: Nominal / partial characterization dominates.
A20: Receiver motion | B20: =COUNTIF(D$8:D$14,"A") | C20: =COUNTIF(D$8:D$14,"B") | D20: =COUNTIF(D$8:D$14,"C") | E20: =COUNTIF(D$8:D$14,"D") | F20: =ROUND(AVERAGE(VLOOKUP(D$8,Lists!$M$2:$N$5,2,FALSE),VLOOKUP(D$9,Lists!$M$2:$N$5,2,FALSE),VLOOKUP(D$10,Lists!$M$2:$N$5,2,FALSE),VLOOKUP(D$11,Lists!$M$2:$N$5,2,FALSE),VLOOKUP(D$12,Lists!$M$2:$N$5,2,FALSE),VLOOKUP(D$13,Lists!$M$2:$N$5,2,FALSE),VLOOKUP(D$14,Lists!$M$2:$N$5,2,FALSE)),2) | G20: Principal physical link remains unmeasured.
A21: Support isolated | B21: =COUNTIF(E$8:E$14,"A") | C21: =COUNTIF(E$8:E$14,"B") | D21: =COUNTIF(E$8:E$14,"C") | E21: =COUNTIF(E$8:E$14,"D") | F21: =ROUND(AVERAGE(VLOOKUP(E$8,Lists!$M$2:$N$5,2,FALSE),VLOOKUP(E$9,Lists!$M$2:$N$5,2,FALSE),VLOOKUP(E$10,Lists!$M$2:$N$5,2,FALSE),VLOOKUP(E$11,Lists!$M$2:$N$5,2,FALSE),VLOOKUP(E$12,Lists!$M$2:$N$5,2,FALSE),VLOOKUP(E$13,Lists!$M$2:$N$5,2,FALSE),VLOOKUP(E$14,Lists!$M$2:$N$5,2,FALSE)),2) | G21: Airborne and structure-borne routes remain confounded.
A22: Thermal / gas sham | B22: =COUNTIF(F$8:F$14,"A") | C22: =COUNTIF(F$8:F$14,"B") | D22: =COUNTIF(F$8:F$14,"C") | E22: =COUNTIF(F$8:F$14,"D") | F22: =ROUND(AVERAGE(VLOOKUP(F$8,Lists!$M$2:$N$5,2,FALSE),VLOOKUP(F$9,Lists!$M$2:$N$5,2,FALSE),VLOOKUP(F$10,Lists!$M$2:$N$5,2,FALSE),VLOOKUP(F$11,Lists!$M$2:$N$5,2,FALSE),VLOOKUP(F$12,Lists!$M$2:$N$5,2,FALSE),VLOOKUP(F$13,Lists!$M$2:$N$5,2,FALSE),VLOOKUP(F$14,Lists!$M$2:$N$5,2,FALSE)),2) | G22: Controls vary; environmental routes remain plausible.
A23: Fruit-level unit | B23: =COUNTIF(G$8:G$14,"A") | C23: =COUNTIF(G$8:G$14,"B") | D23: =COUNTIF(G$8:G$14,"C") | E23: =COUNTIF(G$8:G$14,"D") | F23: =ROUND(AVERAGE(VLOOKUP(G$8,Lists!$M$2:$N$5,2,FALSE),VLOOKUP(G$9,Lists!$M$2:$N$5,2,FALSE),VLOOKUP(G$10,Lists!$M$2:$N$5,2,FALSE),VLOOKUP(G$11,Lists!$M$2:$N$5,2,FALSE),VLOOKUP(G$12,Lists!$M$2:$N$5,2,FALSE),VLOOKUP(G$13,Lists!$M$2:$N$5,2,FALSE),VLOOKUP(G$14,Lists!$M$2:$N$5,2,FALSE)),2) | G23: Outcome unit needs full-text verification in several studies.
A24: Internal replication | B24: =COUNTIF(H$8:H$14,"A") | C24: =COUNTIF(H$8:H$14,"B") | D24: =COUNTIF(H$8:H$14,"C") | E24: =COUNTIF(H$8:H$14,"D") | F24: =ROUND(AVERAGE(VLOOKUP(H$8,Lists!$M$2:$N$5,2,FALSE),VLOOKUP(H$9,Lists!$M$2:$N$5,2,FALSE),VLOOKUP(H$10,Lists!$M$2:$N$5,2,FALSE),VLOOKUP(H$11,Lists!$M$2:$N$5,2,FALSE),VLOOKUP(H$12,Lists!$M$2:$N$5,2,FALSE),VLOOKUP(H$13,Lists!$M$2:$N$5,2,FALSE),VLOOKUP(H$14,Lists!$M$2:$N$5,2,FALSE)),2) | G24: Bounded internal signals exist, but connected lineage limits independence.
A25: External confirmation | B25: =COUNTIF(I$8:I$14,"A") | C25: =COUNTIF(I$8:I$14,"B") | D25: =COUNTIF(I$8:I$14,"C") | E25: =COUNTIF(I$8:I$14,"D") | F25: =ROUND(AVERAGE(VLOOKUP(I$8,Lists!$M$2:$N$5,2,FALSE),VLOOKUP(I$9,Lists!$M$2:$N$5,2,FALSE),VLOOKUP(I$10,Lists!$M$2:$N$5,2,FALSE),VLOOKUP(I$11,Lists!$M$2:$N$5,2,FALSE),VLOOKUP(I$12,Lists!$M$2:$N$5,2,FALSE),VLOOKUP(I$13,Lists!$M$2:$N$5,2,FALSE),VLOOKUP(I$14,Lists!$M$2:$N$5,2,FALSE)),2) | G25: No external transfer identified in retained corpus.

Sheet 07_Contradictions
A1: Contradiction and Rival-Explanation Matrix
A2: Convert apparent disagreement into hidden variables, discriminating measurements, pass conditions and explicit failure interpretations.
A3: ID | B3: Apparent contradiction / claim | C3: Literature clusters | D3: Where evidence agrees | E3: Where evidence differs | F3: Hidden variable / rival explanation | G3: Measurement required | H3: Decisive experiment | I3: Result supporting receiver-centred interpretation | J3: Failure condition / next inference | K3: Evidence class | L3: Priority | M3: Status | N3: Owner | O3: Due date | P3: Notes
A4: X01 | B4: Airborne sound effect versus structure-borne treatment | C4: Airborne-fruit intervention + transport vibration | D4: Multiple routes can move fruit or alter chamber conditions. | E4: Studies attribute outcome to “sound” without route separation. | F4: Loudspeaker reaction force, tray motion, packaging contact or altered microclimate | G4: Pressure and particle velocity, triaxial shelf acceleration, fruit-surface velocity, temperature, airflow and gases | H4: Mechanically isolate the source; include support-only shaker and matched microclimate shams | I4: Outcome follows measured airborne fruit motion after support and environment are bounded | J4: Outcome follows tray acceleration or microclimate; reinterpret the route | K4: Evidence-based inference | L4: High | M4: In progress
A5: X02 | B5: “Fruit resonance” versus chamber, tray or local peel mode | C5: Tomato modal analysis + 1 kHz treatment lineage | D5: Fruit and chambers have frequency-dependent responses. | E5: Treatment uses 1 kHz while reported low-order fruit modes lie in tens of hertz. | F5: Loaded enclosure modes, higher-order fruit modes, local contact modes | G5: Frequency-response function, mode shape, chamber map and support acceleration | H5: Hold local pressure constant on and away from a measured fruit response feature | I5: Response scales with fruit motion rather than on-label frequency | J5: No motion-dependent response; resonance explanation weakens | K5: Evidence-based inference | L5: High | M5: In progress
A6: X03 | B6: Frequency-specific effect versus mechanically equivalent exposure | C6: Airborne-fruit intervention / physical metrology | D6: Source frequency changes receiver response unless amplitude is adjusted. | E6: Studies compare frequency at unequal receiver motion. | F6: Different amplitudes produce different receiver motion at each frequency | G6: Receiver motion or validated strain proxy with uncertainty | H6: Adjust amplitude so two frequencies produce matched receiver exposure | I6: Comparable longitudinal quality at matched exposure | J6: Persistent frequency effect indicates another mechanism or measurement variable | K6: Evidence-based inference | L6: High | M6: In progress
A7: X04 | B7: Total energy versus peak, rate or recovery dependence | C7: Ultrasound pulsed/continuous + fatigue/adaptation literature | D7: Waveform and exposure history can change outcome. | E7: Total energy is often used although peak/rate/recovery may dominate. | F7: Threshold activation, fatigue, crest factor, duty cycle or adaptation | G7: Peak strain, strain rate, cycle count, duty cycle and recovery response | H7: Match total work while varying peak, pulse structure and recovery | I7: Outcome follows the prespecified peak/rate/history variable | J7: No stable exposure–response relation; revise the predictor | K7: Evidence-based inference | L7: Medium | M7: In progress
A8: X05 | B8: Molecular pathway versus maturity marker | C8: Tomato omics + ripening physiology | D8: Molecular markers and maturity co-evolve over time. | E8: Downstream markers are interpreted as mediation without temporal closure. | F8: Sampling at different physiological stages; downstream association without mediation | G8: Motion, calcium/redox, hormone, transcription and quality on nested timescales | H8: Combine route measurement with state-aligned sampling and selective perturbation | I8: Temporal order and attenuation match the proposed chain | J8: Markers follow maturity or remain after pathway disruption | K8: Evidence-based inference | L8: Medium | M8: In progress
A9: X06 | B9: Cavitation effect versus heat or streaming | C9: Liquid power ultrasound / cavitation metrology | D9: Cavitation, streaming and heat co-occur in loaded baths. | E9: Nominal power is treated as cavitation exposure. | F9: Nominal watts, calorimetric heating and mass transfer confounded with bubble activity | G9: Calorimetry, cavitation metric, hydrophone map, dissolved gas and temperature | H9: Match bulk power and temperature while varying measured cavitation activity | I9: Outcome tracks cavitation rather than nominal power or heat | J9: Outcome tracks heat/streaming; do not label it cavitation | K9: Evidence-based inference | L9: Medium | M9: In progress
A10: X07 | B10: Laboratory result versus transferable process | C10: All intervention + scale-up literature | D10: Position, load, batch and equipment affect exposure. | E10: Internal findings are often assumed to transfer without locked estimators. | F10: Position, batch, load, equipment or laboratory dependence | G10: Persistent fruit identity, spatial exposure map, uncertainty and external calibration | H10: Lock the estimator and test a new batch, load, chamber and laboratory | I10: Exposure–quality prediction remains calibrated outside development data | J10: Performance degrades; define a narrower operating domain or missing variable | K10: Evidence-based inference | L10: High | M10: In progress

Sheet 08_Gaps_Innovations
A1: High-Value Research Gaps and Innovation Priorities
A2: Prioritize non-generic gaps by evidence, tractability, impact, falsifiability and industrial leverage.
A3: Gap ID | B3: Precise gap | C3: Explicit / inferred | D3: Evidence it exists | E3: Why it is ignored | F3: Hidden variable / leverage point | G3: Proposed experiment | H3: Key measurements | I3: Expected result | J3: Failure condition | K3: Impact if solved | L3: Feasibility (1–5) | M3: Novelty (1–5) | N3: Citation utility (1–5) | O3: Industrial value (1–5) | P3: Risk (1–5) | Q3: Priority score | R3: Priority | S3: Status | T3: Owner | U3: Time horizon | V3: Source | W3: Notes
A4: G01 | B4: Loaded chamber fields are not linked to fruit motion in the same identified fruit. | C4: Explicit | D4: 0/7 receiver-motion finding; source-to-shelf break. | E4: Requires synchronized acoustic and mechanical metrology under biological loading. | F4: Receiver motion at each product position. | G4: Map pressure/particle velocity/support acceleration and laser-vibrometry response for tagged fruit. | H4: Pa, m s⁻¹, m s⁻², FRF, uncertainty, position. | I4: Explains variance and identifies dominant route. | J4: Motion does not improve prediction over source settings. | K4: Causal closure; common basis for scale-up. | L4: 4 | M4: 5 | N4: 5 | O4: 5 | P4: 3 | Q4: =ROUND((L4*0.20+M4*0.20+N4*0.20+O4*0.25+(6-P4)*0.15)*20,1) | R4: Critical | S4: In progress | U4: 12–24 months | V4: Table 2 / Figure 3
A5: G02 | B5: Airborne and structure-borne routes are not experimentally separated. | C5: Explicit | D5: Support isolation graded D across retained corpus. | E5: Speaker reaction force and tray contact are easy to overlook. | F5: Gate-zero route identification. | G5: Mechanically isolate source; support-only shaker; matched microclimate shams. | H5: Tray acceleration, fruit motion, pressure field, airflow, temperature. | I5: Outcome follows one bounded route. | J5: Multiple uncontrolled routes remain inseparable. | K5: Prevents misclassification of treatment mechanism. | L5: 5 | M5: 5 | N5: 5 | O5: 5 | P5: 2 | Q5: =ROUND((L5*0.20+M5*0.20+N5*0.20+O5*0.25+(6-P5)*0.15)*20,1) | R5: Critical | S5: In progress | U5: 6–12 months | V5: Table 3 FP0
A6: G03 | B6: Receiver state is not used to interpret or control exposure. | C6: Explicit | D6: Fruit stiffness, damping, turgor and contact evolve during storage. | E6: Requires pretreatment sensing and hierarchical modelling. | F6: State-dependent transfer function H(f,x). | G6: Measure baseline mechanical state; map state×exposure interaction longitudinally. | H6: Mass, geometry, temperature, FRF, damping, maturity, response. | I6: State explains exposure heterogeneity and shifts operating window. | J6: No reproducible state dependence or poor transfer. | K6: Enables precision treatment and prevents over/undertreatment. | L6: 4 | M6: 4 | N6: 5 | O6: 5 | P6: 3 | Q6: =ROUND((L6*0.20+M6*0.20+N6*0.20+O6*0.25+(6-P6)*0.15)*20,1) | R6: High | S6: Not started | U6: 12–24 months | V6: Section 3.3
A7: G04 | B7: Surface motion is not validated as internal tissue strain. | C7: Explicit | D7: Vibrometry measures surface velocity; mechanotransduction requires local deformation. | E7: Inverse problem requires material properties, boundary conditions and calibration. | F7: Surface-to-tissue reconstruction with uncertainty. | G7: Combine LDV, imaging/tomography and destructive calibration subset with finite-element model. | H7: Surface field, internal displacement/strain, material parameters, model error. | I7: Validated strain proxy predicts biology better than surface motion alone. | J7: Model error remains too high or non-identifiable. | K7: Makes mechanotransduction claims testable. | L7: 3 | M7: 5 | N7: 5 | O7: 4 | P7: 4 | Q7: =ROUND((L7*0.20+M7*0.20+N7*0.20+O7*0.25+(6-P7)*0.15)*20,1) | R7: High | S7: Not started | U7: 18–36 months | V7: Section 3.3
A8: G05 | B8: No validated receiver-equivalence criterion transfers treatment across devices. | C8: Inferred | D8: Different systems may use different settings yet produce similar exposure. | E8: Requires equivalence margins and external validation rather than optimization alone. | F8: Distance between exposure distributions and shelf trajectories. | G8: Develop in Chamber A; retune Chamber B; lock estimator; test new batch/lab. | H8: Exposure distribution, uncertainty, trajectory distance, calibration. | I8: Matched exposure yields equivalent shelf trajectory. | J8: Quality diverges despite matched measured exposure. | K8: Defines device-independent process identity. | L8: 3 | M8: 5 | N8: 5 | O8: 5 | P8: 4 | Q8: =ROUND((L8*0.20+M8*0.20+N8*0.20+O8*0.25+(6-P8)*0.15)*20,1) | R8: Critical | S8: Not started | U8: 24–36 months | V8: Figure 4 / Section 6.3
A9: G06 | B9: Shelf claims rely on isolated endpoints instead of complete trajectories. | C9: Explicit | D9: Firmness, gases and metabolites depend on timing and physiological state. | E9: Longitudinal studies are resource intensive and require correct units. | F9: Trajectory alignment at equal time and equal physiological state. | G9: Track onset, peak, area, texture, colour, gases, mass loss, damage and sensory endpoints. | H9: Repeated measures and hierarchical trajectory model. | I9: Clarifies whether treatment delays, suppresses or redistributes response. | J9: Single endpoint remains inconsistent with trajectory. | K9: Converts laboratory outcomes into shelf decisions. | L9: 4 | M9: 4 | N9: 5 | O9: 5 | P9: 3 | Q9: =ROUND((L9*0.20+M9*0.20+N9*0.20+O9*0.25+(6-P9)*0.15)*20,1) | R9: High | S9: In progress | U9: 12–24 months | V9: Section 7.1
A10: G07 | B10: Experimental units and replication are often mismatched to exposure and outcome. | C10: Explicit | D10: Fruit, vessel and chamber can be different units. | E10: Many assays create technical replicates that look like biological replication. | F10: Correct hierarchical unitization. | G10: Design chamber/run, vessel and fruit replication with randomization across batch and position. | H10: Variance components, ICC, run/batch effects. | I10: Valid uncertainty and reproducible inference. | J10: Pseudoreplication dominates the result. | K10: Improves reliability across the field. | L10: 5 | M10: 4 | N10: 5 | O10: 4 | P10: 2 | Q10: =ROUND((L10*0.20+M10*0.20+N10*0.20+O10*0.25+(6-P10)*0.15)*20,1) | R10: Critical | S10: Not started | U10: 6–12 months | V10: Section 3.4 / S5
A11: G08 | B11: Every fruit cannot be instrumented in a dense chamber. | C11: Explicit | D11: Occlusion, contact and throughput prevent per-fruit measurement. | E11: Practical sensing architecture remains undeveloped. | F11: Sentinel fruit + batch-state distribution. | G11: Validate sentinel placement and estimator across loads, positions and batches. | H11: Sentinel response, batch state, prediction intervals, out-of-domain detection. | I11: Small sensor set predicts exposure distribution with calibrated uncertainty. | J11: Sentinels fail under load changes. | K11: Enables practical commissioning and control. | L11: 4 | M11: 5 | N11: 5 | O11: 5 | P11: 3 | Q11: =ROUND((L11*0.20+M11*0.20+N11*0.20+O11*0.25+(6-P11)*0.15)*20,1) | R11: High | S11: Not started | U11: 12–24 months | V11: Section 3.4 / Figure S2
